Workbook

Sheet 🏠 Hoje
A1: 🏗️ PAINEL DA OBRA - Consulado Geral da Itália
A2: ="Hoje: "&TEXT(TODAY(),"dd/mm/yyyy")&" - "&TEXT(TODAY(),"dddd") -> Hoje: 28/06/2026 - domingo
A4: 🚨 Atrasados | B4: ⏳ Em andamento | C4: 📅 A iniciar | D4: ✅ Concluídos | E4: 📋 Subitens total | F4: 💼 Subitens hoje
A5: =COUNTIF(Gestao!F8:F171,"Atrasado") -> 57 | B5: =COUNTIF(Gestao!F8:F171,"Em andamento") -> 32 | C5: =COUNTIF(Gestao!F8:F171,"A iniciar") -> 74 | D5: =COUNTIF(Gestao!$G$8:$G$500,"Finalizado") -> 0 | E5: =COUNTA(Detalhamento!A9:A329) -> 321 | F5: =SUMPRODUCT((Detalhamento!E9:E329<=TODAY())*(Detalhamento!F9:F329>=TODAY())*(Detalhamento!A9:A329<>"")) -> 0
A7: 🚨 SUBITENS ATRASADOS
A8: Item Principal | B8: Subitem | C8: Atividade | D8: Descrição | E8: Término | F8: Status
A9: =IFERROR(__xludf.DUMMYFUNCTION("IFERROR(QUERY(Detalhamento!A9:H2020,""select A,B,C,D,F,H where A is not null and H <> 'Concluído' and F < date '""&TEXT(TODAY(),""yyyy-mm-dd"")&""' order by F limit 50"",0),""Nenhum subitem atrasado"")"),"Nenhum subitem atrasado") -> Nenhum subitem atrasado
A62: 📅 PRÓXIMOS 15 DIAS
A63: Item Principal | B63: Subitem | C63: Atividade | D63: Descrição | E63: Início | F63: Status
A64: =IFERROR(__xludf.DUMMYFUNCTION("IFERROR(QUERY(Detalhamento!A9:H2020,""select A,B,C,D,E,H where A is not null and E >= date '""&TEXT(TODAY(),""yyyy-mm-dd"")&""' and E <= date '""&TEXT(TODAY()+15,""yyyy-mm-dd"")&""' order by E limit 50"",0),""Nada nos próximos 15 dias"")"),"Nada nos próximos 15 dias") -> Nada nos próximos 15 dias
A117: 💰 PAGAMENTOS A FAZER (próx. 7 dias)
A118: Tipo | B118: Beneficiário | C118: Descrição | D118: Valor | E118: Vencimento | F118: Status
A119: =IFERROR(__xludf.DUMMYFUNCTION("IFERROR(QUERY(Pagamentos!A7:V600,""select A,B,D,N,O,R where O >= date '""&TEXT(TODAY(),""yyyy-mm-dd"")&""' and O <= date '""&TEXT(TODAY()+7,""yyyy-mm-dd"")&""' and R <> 'Pago' order by O limit 30"",0),""Nenhum pagamento nos próximos 7 dias"")"),"Nenhum pagamento nos próximos 7 dias") -> Nenhum pagamento nos próximos 7 dias

Sheet 📊 Dashboard
A1: 📊 PAINEL DA OBRA — Consulado Geral da Itália
A2: Avanço · Prazos · Materiais — atualizado automático
A4: ATRASADOS | C4: EM ANDAMENTO | E4: A INICIAR | G4: CONCLUÍDOS | I4: SUBITENS | K4: % AVANÇO
A5: ='🏠 Hoje'!A5 -> 57 | C5: ='🏠 Hoje'!B5 -> 32 | E5: ='🏠 Hoje'!C5 -> 74 | G5: ='🏠 Hoje'!D5 -> 0 | I5: ='🏠 Hoje'!E5 -> 321 | K5: =IFERROR(AVERAGEIFS(Detalhamento!O8:O1000,Detalhamento!C8:C1000,"<>"),0) -> 0
A7: 📈 AVANÇO POR DISCIPLINA | E7: ⏰ PRÓXIMOS VENCIMENTOS | I7: 🧱 ESTOQUE ATUAL
A8: Disciplina | B8: Subitens | C8: % Avanço | D8: Volume | E8: Item | F8: Atividade | G8: Término | I8: Material | J8: Categoria | K8: Estoque
A9: Preliminares | B9: =COUNTIF(Detalhamento!$G$8:$G1000,A9) -> 4 | C9: =IFERROR(AVERAGEIF(Detalhamento!$G$8:$G1000,A9,Detalhamento!$O$8:$O1000),0) -> 0 | D9: =IF(B9=0,"",REPT("▮",MAX(1,ROUND(B9/MAX($B$9:$B$23)*12,0)))) -> ▮ | E9: {=IF($AA9:$AA24="","",$AA9:$AA24)} -> 1.1 | F9: {=IF($AB9:$AB24="","",IF(LEN($AB9:$AB24)>50,LEFT($AB9:$AB24,49)&"…",$AB9:$AB24))} -> Gerenciamento técnico de obra - 2 Engenheiros (40… | G9: {=IF($AC9:$AC24="","",$AC9:$AC24)} | I9: =IFERROR(__xludf.DUMMYFUNCTION("QUERY(Inventario!A6:H1000,""select A,B,F where F > 0 order by F desc limit 16"",0)"),"Areia media lavada") -> Areia media lavada | J9: =IFERROR(__xludf.DUMMYFUNCTION("""COMPUTED_VALUE"""),"Material") -> Material | K9: =IFERROR(__xludf.DUMMYFUNCTION("""COMPUTED_VALUE"""),318.0) -> 318 | AA9: =IFERROR(__xludf.DUMMYFUNCTION("ARRAY_CONSTRAIN(UNIQUE(FILTER({Detalhamento!A8:A1000,Detalhamento!C8:C1000,Detalhamento!F8:F1000},(Detalhamento!C8:C1000<>"""")*(Detalhamento!H8:H1000<>""Concluído""))),16,3)"),"1.1") -> 1.1 | AB9: =IFERROR(__xludf.DUMMYFUNCTION("""COMPUTED_VALUE"""),"Gerenciamento técnico de obra - 2 Engenheiros (40h/mês) , assistente tecnico (40h/mês) , mestre de obra (160h/mês)") -> Gerenciamento técnico de obra - 2 Engenheiros (40h/mês) , assistente tecnico (40h/mês) , mestre de obra (160h/mês)
A10: Civil | B10: =COUNTIF(Detalhamento!$G$8:$G1000,A10) -> 281 | C10: =IFERROR(AVERAGEIF(Detalhamento!$G$8:$G1000,A10,Detalhamento!$O$8:$O1000),0) -> 0 | D10: =IF(B10=0,"",REPT("▮",MAX(1,ROUND(B10/MAX($B$9:$B$23)*12,0)))) -> ▮▮▮▮▮▮▮▮▮▮▮▮ | E10: 1.3 | F10: Mobilização de canteiro e equipes e deslocamento | I10: =IFERROR(__xludf.DUMMYFUNCTION("""COMPUTED_VALUE"""),"Cimento CP-II 50kg") -> Cimento CP-II 50kg | J10: =IFERROR(__xludf.DUMMYFUNCTION("""COMPUTED_VALUE"""),"Material") -> Material | K10: =IFERROR(__xludf.DUMMYFUNCTION("""COMPUTED_VALUE"""),50.0) -> 50 | AA10: =IFERROR(__xludf.DUMMYFUNCTION("""COMPUTED_VALUE"""),"1.3") -> 1.3 | AB10: =IFERROR(__xludf.DUMMYFUNCTION("""COMPUTED_VALUE"""),"Mobilização de canteiro e equipes e deslocamento") -> Mobilização de canteiro e equipes e deslocamento
A11: Demolições | B11: =COUNTIF(Detalhamento!$G$8:$G1000,A11) -> 0 | C11: =IFERROR(AVERAGEIF(Detalhamento!$G$8:$G1000,A11,Detalhamento!$O$8:$O1000),0) -> 0 | D11: =IF(B11=0,"",REPT("▮",MAX(1,ROUND(B11/MAX($B$9:$B$23)*12,0)))) | E11: 1.4 | F11: Tapume de vedacao ou protecao, executado com chap… | AA11: =IFERROR(__xludf.DUMMYFUNCTION("""COMPUTED_VALUE"""),"1.4") -> 1.4 | AB11: =IFERROR(__xludf.DUMMYFUNCTION("""COMPUTED_VALUE"""),"Tapume de vedacao ou protecao, executado com chapas de compensado, tipo chapa resinada ou similar, com 6mm de espessura, exclusive pintura. Proteção chegada elvadores;.") -> Tapume de vedacao ou protecao, executado com chapas de compensado, tipo chapa resinada ou similar, com 6mm de espessura, exclusive pintura. Proteção chegada elvadores;.
A12: Revestimento | B12: =COUNTIF(Detalhamento!$G$8:$G1000,A12) -> 85 | C12: =IFERROR(AVERAGEIF(Detalhamento!$G$8:$G1000,A12,Detalhamento!$O$8:$O1000),0) -> 0 | D12: =IF(B12=0,"",REPT("▮",MAX(1,ROUND(B12/MAX($B$9:$B$23)*12,0)))) -> ▮▮▮▮ | E12: 1.5 | F12: Limpeza permanente de obra | AA12: =IFERROR(__xludf.DUMMYFUNCTION("""COMPUTED_VALUE"""),"1.5") -> 1.5 | AB12: =IFERROR(__xludf.DUMMYFUNCTION("""COMPUTED_VALUE"""),"Limpeza permanente de obra") -> Limpeza permanente de obra
A13: Pintura | B13: =COUNTIF(Detalhamento!$G$8:$G1000,A13) -> 65 | C13: =IFERROR(AVERAGEIF(Detalhamento!$G$8:$G1000,A13,Detalhamento!$O$8:$O1000),0) -> 0 | D13: =IF(B13=0,"",REPT("▮",MAX(1,ROUND(B13/MAX($B$9:$B$23)*12,0)))) -> ▮▮▮ | E13: 2.1 | F13: Demolicão manual de alvenaria de tijolos furados,… | AA13: =IFERROR(__xludf.DUMMYFUNCTION("""COMPUTED_VALUE"""),"2.1") -> 2.1 | AB13: =IFERROR(__xludf.DUMMYFUNCTION("""COMPUTED_VALUE"""),"Demolicão manual de alvenaria de tijolos furados, contrapiso de 5 cm no deposito 5, inclusive empilhamento dentro do canteiro de servico.") -> Demolicão manual de alvenaria de tijolos furados, contrapiso de 5 cm no deposito 5, inclusive empilhamento dentro do canteiro de servico.
A14: Elétrica | B14: =COUNTIF(Detalhamento!$G$8:$G1000,A14) -> 0 | C14: =IFERROR(AVERAGEIF(Detalhamento!$G$8:$G1000,A14,Detalhamento!$O$8:$O1000),0) -> 0 | D14: =IF(B14=0,"",REPT("▮",MAX(1,ROUND(B14/MAX($B$9:$B$23)*12,0)))) | E14: 2.2 | F14: Demolição controlada e monitrada para rebaixament… | AA14: =IFERROR(__xludf.DUMMYFUNCTION("""COMPUTED_VALUE"""),"2.2") -> 2.2 | AB14: =IFERROR(__xludf.DUMMYFUNCTION("""COMPUTED_VALUE"""),"Demolição controlada e monitrada para rebaixamento da laje e abertura na laje superior e dos vãos de portas nos andares") -> Demolição controlada e monitrada para rebaixamento da laje e abertura na laje superior e dos vãos de portas nos andares
A15: Hidráulica | B15: =COUNTIF(Detalhamento!$G$8:$G1000,A15) -> 0 | C15: =IFERROR(AVERAGEIF(Detalhamento!$G$8:$G1000,A15,Detalhamento!$O$8:$O1000),0) -> 0 | D15: =IF(B15=0,"",REPT("▮",MAX(1,ROUND(B15/MAX($B$9:$B$23)*12,0)))) | E15: 2.3 | F15: Caçamba para entulho 4m³ | AA15: =IFERROR(__xludf.DUMMYFUNCTION("""COMPUTED_VALUE"""),"2.3") -> 2.3 | AB15: =IFERROR(__xludf.DUMMYFUNCTION("""COMPUTED_VALUE"""),"Caçamba para entulho 4m³") -> Caçamba para entulho 4m³
A16: Instalacoes | B16: =COUNTIF(Detalhamento!$G$8:$G1000,A16) -> 12 | C16: =IFERROR(AVERAGEIF(Detalhamento!$G$8:$G1000,A16,Detalhamento!$O$8:$O1000),0) -> 0 | D16: =IF(B16=0,"",REPT("▮",MAX(1,ROUND(B16/MAX($B$9:$B$23)*12,0)))) -> ▮ | E16: 2.4 | F16: Transporte de entulho e grades | AA16: =IFERROR(__xludf.DUMMYFUNCTION("""COMPUTED_VALUE"""),"2.4") -> 2.4 | AB16: =IFERROR(__xludf.DUMMYFUNCTION("""COMPUTED_VALUE"""),"Transporte de entulho e grades") -> Transporte de entulho e grades
A17: Esquadrias | B17: =COUNTIF(Detalhamento!$G$8:$G1000,A17) -> 28 | C17: =IFERROR(AVERAGEIF(Detalhamento!$G$8:$G1000,A17,Detalhamento!$O$8:$O1000),0) -> 0 | D17: =IF(B17=0,"",REPT("▮",MAX(1,ROUND(B17/MAX($B$9:$B$23)*12,0)))) -> ▮ | E17: 2.5 | F17: Caçamba para entulho 4m³ | AA17: =IFERROR(__xludf.DUMMYFUNCTION("""COMPUTED_VALUE"""),"2.5") -> 2.5 | AB17: =IFERROR(__xludf.DUMMYFUNCTION("""COMPUTED_VALUE"""),"Caçamba para entulho 4m³") -> Caçamba para entulho 4m³
A18: Serralheria | B18: =COUNTIF(Detalhamento!$G$8:$G1000,A18) -> 48 | C18: =IFERROR(AVERAGEIF(Detalhamento!$G$8:$G1000,A18,Detalhamento!$O$8:$O1000),0) -> 0 | D18: =IF(B18=0,"",REPT("▮",MAX(1,ROUND(B18/MAX($B$9:$B$23)*12,0)))) -> ▮▮ | E18: 2.6 | F18: Transporte de entulho | AA18: =IFERROR(__xludf.DUMMYFUNCTION("""COMPUTED_VALUE"""),"2.6") -> 2.6 | AB18: =IFERROR(__xludf.DUMMYFUNCTION("""COMPUTED_VALUE"""),"Transporte de entulho") -> Transporte de entulho
A19: Forro | B19: =COUNTIF(Detalhamento!$G$8:$G1000,A19) -> 38 | C19: =IFERROR(AVERAGEIF(Detalhamento!$G$8:$G1000,A19,Detalhamento!$O$8:$O1000),0) -> 0 | D19: =IF(B19=0,"",REPT("▮",MAX(1,ROUND(B19/MAX($B$9:$B$23)*12,0)))) -> ▮▮ | E19: 2.7 | F19: Montagem e desmontagem de andaime direcional estr… | AA19: =IFERROR(__xludf.DUMMYFUNCTION("""COMPUTED_VALUE"""),"2.7") -> 2.7 | AB19: =IFERROR(__xludf.DUMMYFUNCTION("""COMPUTED_VALUE"""),"Montagem e desmontagem de andaime direcional estrutural com chumbadores e plataforma") -> Montagem e desmontagem de andaime direcional estrutural com chumbadores e plataforma
A20: Climatizacao | B20: =COUNTIF(Detalhamento!$G$8:$G1000,A20) -> 23 | C20: =IFERROR(AVERAGEIF(Detalhamento!$G$8:$G1000,A20,Detalhamento!$O$8:$O1000),0) -> 0 | D20: =IF(B20=0,"",REPT("▮",MAX(1,ROUND(B20/MAX($B$9:$B$23)*12,0)))) -> ▮ | E20: 3.1 | F20: Construção do prolongamento da caixa do elevador | AA20: =IFERROR(__xludf.DUMMYFUNCTION("""COMPUTED_VALUE"""),"3.1") -> 3.1 | AB20: =IFERROR(__xludf.DUMMYFUNCTION("""COMPUTED_VALUE"""),"Construção do prolongamento da caixa do elevador") -> Construção do prolongamento da caixa do elevador
A21: Impermeabilizacao | B21: =COUNTIF(Detalhamento!$G$8:$G1000,A21) -> 16 | C21: =IFERROR(AVERAGEIF(Detalhamento!$G$8:$G1000,A21,Detalhamento!$O$8:$O1000),0) -> 0 | D21: =IF(B21=0,"",REPT("▮",MAX(1,ROUND(B21/MAX($B$9:$B$23)*12,0)))) -> ▮ | E21: 3.2 | F21: Construção da laje de cobertura da torre com Alça… | AA21: =IFERROR(__xludf.DUMMYFUNCTION("""COMPUTED_VALUE"""),"3.2") -> 3.2 | AB21: =IFERROR(__xludf.DUMMYFUNCTION("""COMPUTED_VALUE"""),"Construção da laje de cobertura da torre com Alça para içamento do pistão") -> Construção da laje de cobertura da torre com Alça para içamento do pistão
A22: Elevadores | B22: =COUNTIF(Detalhamento!$G$8:$G1000,A22) -> 31 | C22: =IFERROR(AVERAGEIF(Detalhamento!$G$8:$G1000,A22,Detalhamento!$O$8:$O1000),0) -> 0 | D22: =IF(B22=0,"",REPT("▮",MAX(1,ROUND(B22/MAX($B$9:$B$23)*12,0)))) -> ▮ | E22: 3.3 | F22: Cintas intermediárias em todos os andares | AA22: =IFERROR(__xludf.DUMMYFUNCTION("""COMPUTED_VALUE"""),"3.3") -> 3.3 | AB22: =IFERROR(__xludf.DUMMYFUNCTION("""COMPUTED_VALUE"""),"Cintas intermediárias em todos os andares") -> Cintas intermediárias em todos os andares
A23: Limpeza | B23: =COUNTIF(Detalhamento!$G$8:$G1000,A23) -> 6 | C23: =IFERROR(AVERAGEIF(Detalhamento!$G$8:$G1000,A23,Detalhamento!$O$8:$O1000),0) -> 0 | D23: =IF(B23=0,"",REPT("▮",MAX(1,ROUND(B23/MAX($B$9:$B$23)*12,0)))) -> ▮ | E23: 3.4 | F23: Fechamento das laterais e fundos em alvenaria no … | AA23: =IFERROR(__xludf.DUMMYFUNCTION("""COMPUTED_VALUE"""),"3.4") -> 3.4 | AB23: =IFERROR(__xludf.DUMMYFUNCTION("""COMPUTED_VALUE"""),"Fechamento das laterais e fundos em alvenaria no prolongamento da torre") -> Fechamento das laterais e fundos em alvenaria no prolongamento da torre
E24: 3.5 | F24: Rebocamento no prolongamento da torre | AA24: =IFERROR(__xludf.DUMMYFUNCTION("""COMPUTED_VALUE"""),"3.5") -> 3.5 | AB24: =IFERROR(__xludf.DUMMYFUNCTION("""COMPUTED_VALUE"""),"Rebocamento no prolongamento da torre") -> Rebocamento no prolongamento da torre
A26: 🔴 BLOQUEIOS (itens parados) | E26: 💰 MATERIAL / COMPRAS | I26: 🔗 COMPATIBILIZAÇÃO
A27: Motivo | B27: Qtd | E27: Indicador | F27: Valor | I27: Indicador | J27: Valor
A28: Falta pessoa | B28: =COUNTIF(Detalhamento!J8:J1000,"Não") -> 0 | E28: Total material (qtd x valor) | F28: =SUMPRODUCT(SC!H6:H205,SC!J6:J205) -> 14422.64 | I28: Itens de contrato | J28: =COUNTA(Compatibilizacao!A5:A1000) -> 996
A29: Falta documento | B29: =COUNTIF(Detalhamento!K8:K1000,"Não") -> 0 | E29: Lançamentos de compra | F29: =COUNTA(SC!D6:D205) -> 7 | I29: Com orçamento | J29: =COUNTIF(Compatibilizacao!F5:F1000,"*🟢*") -> 42
A30: Falta material | B30: =COUNTIF(Detalhamento!L8:L1000,"Não") -> 0 | E30: Itens em estoque (>0) | F30: =COUNTIF(Inventario!F6:F1000,">0") -> 2 | I30: SEM orçamento | J30: =COUNTIF(Compatibilizacao!F5:F1000,"*🔴*") -> 126
A31: Falta ferramenta | B31: =COUNTIF(Detalhamento!M8:M1000,"Não") -> 0 | I31: % cobertura | J31: =IFERROR(COUNTIF(Compatibilizacao!F5:F1000,"*🟢*")/COUNTA(Compatibilizacao!A5:A1000),0) -> 0.042168675
A32: Falta equipamento | B32: =COUNTIF(Detalhamento!N8:N1000,"Não") -> 0

Sheet AUX_ItensContrato
A1: NOVO
A2: 46023
A3: 46054
A4: 46082
A5: 46113
A6: 46143
A7: 46024
A8: 46055
A9: 46083
A10: 46114
A11: 46144
A12: 46175
A13: 46205
... A31: 46360
A32: 4.13
A33: 4.14
A34: 4.15
A35: 4.16
A36: 4.17
A37: 11
A38: 12
A39: 12
A40: 46034
A41: 13
A42: 14
A43: 46035
A44: 46027
A45: 46058
A46: 46086
A47: 46117
A48: 46147
... A55: 46361
A56: 5.13
A57: 5.14
A58: 5.15
A59: 5.16
A60: 5.17
A61: 5.18
A62: 5.19
A63: 5.20
...

Sheet Dashboard_OLD
B1: 📊 DASHBOARD DA OBRA
B2: ="Consulado Geral da Itália · atualizado em "&TEXT(TODAY(),"dd/mm/yyyy") -> Consulado Geral da Itália · atualizado em 28/06/2026
B4: % AVANÇO FÍSICO | D4: ETAPAS CONCLUÍDAS | F4: ITENS ATRASADOS | I4: ENTREGAS 30 DIAS | K4: PAGO / PREVISTO
B5: =IFERROR(COUNTIF(Detalhamento!$H$9:$H1000,"Concluído")/COUNTA(Detalhamento!$H$9:$H1000),0) -> 0.0066518847 | D5: =COUNTIF(Detalhamento!$H$9:$H1000,"Concluído")&" / "&COUNTA(Detalhamento!$H$9:$H1000) -> 6 / 902 | F5: =COUNTIF(Gestao!$F$4:$F1000,"Atrasado") -> 58 | I5: =COUNTIFS(Gestao!$E$4:$E1000,">="&TODAY(),Gestao!$E$4:$E1000,"<="&TODAY()+30) -> 7 | K5: =IFERROR(TEXT(Orcamentos!$Q$6,"R$ #.##0")&" / "&TEXT(Orcamentos!$O$6,"R$ #.##0"),"—") -> R$ ,0 / R$ ,0
B8: PROGRESSO POR STATUS — etapas | H8: POR SEGMENTO — etapas
B9: Status | C9: Qtd | D9: % | E9: Barra | H9: Segmento | I9: Etapas | J9: Concl. | K9: % | L9: Barra
B10: Concluído | C10: =COUNTIF(Detalhamento!$H$9:$H1000,"Concluído") -> 6 | D10: =IFERROR(C10/COUNTA(Detalhamento!$H$9:$H1000),0) -> 0.0066518847 | E10: =IFERROR(REPT("▮",ROUND(D10*20,0)),"") | H10: Civil | I10: =COUNTIF(Detalhamento!$G$9:$G1000,"Civil") -> 281 | J10: =COUNTIFS(Detalhamento!$G$9:$G1000,"Civil",Detalhamento!$H$9:$H1000,"Concluído") -> 0 | K10: =IFERROR(J10/I10,0) -> 0 | L10: =IFERROR(REPT("▮",ROUND(K10*12,0)),"")
B11: Em andamento | C11: =COUNTIF(Detalhamento!$H$9:$H1000,"Em andamento") -> 2 | D11: =IFERROR(C11/COUNTA(Detalhamento!$H$9:$H1000),0) -> 0.0022172949 | E11: =IFERROR(REPT("▮",ROUND(D11*20,0)),"") | H11: Estrutura | I11: =COUNTIF(Detalhamento!$G$9:$G1000,"Estrutura") -> 0 | J11: =COUNTIFS(Detalhamento!$G$9:$G1000,"Estrutura",Detalhamento!$H$9:$H1000,"Concluído") -> 0 | K11: =IFERROR(J11/I11,0) -> 0 | L11: =IFERROR(REPT("▮",ROUND(K11*12,0)),"")
B12: A iniciar | C12: =COUNTIF(Detalhamento!$H$9:$H1000,"A iniciar") -> 894 | D12: =IFERROR(C12/COUNTA(Detalhamento!$H$9:$H1000),0) -> 0.99113082 | E12: =IFERROR(REPT("▮",ROUND(D12*20,0)),"") -> ▮▮▮▮▮▮▮▮▮▮▮▮▮▮▮▮▮▮▮▮ | H12: Instalacoes | I12: =COUNTIF(Detalhamento!$G$9:$G1000,"Instalacoes") -> 12 | J12: =COUNTIFS(Detalhamento!$G$9:$G1000,"Instalacoes",Detalhamento!$H$9:$H1000,"Concluído") -> 0 | K12: =IFERROR(J12/I12,0) -> 0 | L12: =IFERROR(REPT("▮",ROUND(K12*12,0)),"")
H13: Hidraulica | I13: =COUNTIF(Detalhamento!$G$9:$G1000,"Hidraulica") -> 30 | J13: =COUNTIFS(Detalhamento!$G$9:$G1000,"Hidraulica",Detalhamento!$H$9:$H1000,"Concluído") -> 0 | K13: =IFERROR(J13/I13,0) -> 0 | L13: =IFERROR(REPT("▮",ROUND(K13*12,0)),"")
B14: POR ANDAR / ÁREA — itens (Gestão) | H14: Eletrica | I14: =COUNTIF(Detalhamento!$G$9:$G1000,"Eletrica") -> 86 | J14: =COUNTIFS(Detalhamento!$G$9:$G1000,"Eletrica",Detalhamento!$H$9:$H1000,"Concluído") -> 0 | K14: =IFERROR(J14/I14,0) -> 0 | L14: =IFERROR(REPT("▮",ROUND(K14*12,0)),"")
B15: Área | C15: Itens | D15: Atrasado | E15: Em and. | F15: A iniciar | H15: Climatizacao | I15: =COUNTIF(Detalhamento!$G$9:$G1000,"Climatizacao") -> 23 | J15: =COUNTIFS(Detalhamento!$G$9:$G1000,"Climatizacao",Detalhamento!$H$9:$H1000,"Concluído") -> 0 | K15: =IFERROR(J15/I15,0) -> 0 | L15: =IFERROR(REPT("▮",ROUND(K15*12,0)),"")
B16: Andar 8 | C16: =COUNTIF(Gestao!$C$4:$C1000,"Andar 8") -> 49 | D16: =COUNTIFS(Gestao!$C$4:$C1000,"Andar 8",Gestao!$F$4:$F1000,"Atrasado") -> 19 | E16: =COUNTIFS(Gestao!$C$4:$C1000,"Andar 8",Gestao!$F$4:$F1000,"Em andamento") -> 8 | F16: =COUNTIFS(Gestao!$C$4:$C1000,"Andar 8",Gestao!$F$4:$F1000,"A iniciar") -> 21 | H16: Revestimento | I16: =COUNTIF(Detalhamento!$G$9:$G1000,"Revestimento") -> 85 | J16: =COUNTIFS(Detalhamento!$G$9:$G1000,"Revestimento",Detalhamento!$H$9:$H1000,"Concluído") -> 0 | K16: =IFERROR(J16/I16,0) -> 0 | L16: =IFERROR(REPT("▮",ROUND(K16*12,0)),"")
B17: Andar 9 | C17: =COUNTIF(Gestao!$C$4:$C1000,"Andar 9") -> 37 | D17: =COUNTIFS(Gestao!$C$4:$C1000,"Andar 9",Gestao!$F$4:$F1000,"Atrasado") -> 15 | E17: =COUNTIFS(Gestao!$C$4:$C1000,"Andar 9",Gestao!$F$4:$F1000,"Em andamento") -> 6 | F17: =COUNTIFS(Gestao!$C$4:$C1000,"Andar 9",Gestao!$F$4:$F1000,"A iniciar") -> 16 | H17: Forro | I17: =COUNTIF(Detalhamento!$G$9:$G1000,"Forro") -> 38 | J17: =COUNTIFS(Detalhamento!$G$9:$G1000,"Forro",Detalhamento!$H$9:$H1000,"Concluído") -> 0 | K17: =IFERROR(J17/I17,0) -> 0 | L17: =IFERROR(REPT("▮",ROUND(K17*12,0)),"")
B18: Roof Top | C18: =COUNTIF(Gestao!$C$4:$C1000,"Roof Top") -> 12 | D18: =COUNTIFS(Gestao!$C$4:$C1000,"Roof Top",Gestao!$F$4:$F1000,"Atrasado") -> 6 | E18: =COUNTIFS(Gestao!$C$4:$C1000,"Roof Top",Gestao!$F$4:$F1000,"Em andamento") -> 0 | F18: =COUNTIFS(Gestao!$C$4:$C1000,"Roof Top",Gestao!$F$4:$F1000,"A iniciar") -> 6 | H18: Pintura | I18: =COUNTIF(Detalhamento!$G$9:$G1000,"Pintura") -> 65 | J18: =COUNTIFS(Detalhamento!$G$9:$G1000,"Pintura",Detalhamento!$H$9:$H1000,"Concluído") -> 0 | K18: =IFERROR(J18/I18,0) -> 0 | L18: =IFERROR(REPT("▮",ROUND(K18*12,0)),"")
B19: Elevadores | C19: =COUNTIF(Gestao!$C$4:$C1000,"Elevadores") -> 41 | D19: =COUNTIFS(Gestao!$C$4:$C1000,"Elevadores",Gestao!$F$4:$F1000,"Atrasado") -> 11 | E19: =COUNTIFS(Gestao!$C$4:$C1000,"Elevadores",Gestao!$F$4:$F1000,"Em andamento") -> 16 | F19: =COUNTIFS(Gestao!$C$4:$C1000,"Elevadores",Gestao!$F$4:$F1000,"A iniciar") -> 11 | H19: Esquadrias | I19: =COUNTIF(Detalhamento!$G$9:$G1000,"Esquadrias") -> 28 | J19: =COUNTIFS(Detalhamento!$G$9:$G1000,"Esquadrias",Detalhamento!$H$9:$H1000,"Concluído") -> 0 | K19: =IFERROR(J19/I19,0) -> 0 | L19: =IFERROR(REPT("▮",ROUND(K19*12,0)),"")
B20: Preliminares | C20: =COUNTIF(Gestao!$C$4:$C1000,"Preliminares") -> 5 | D20: =COUNTIFS(Gestao!$C$4:$C1000,"Preliminares",Gestao!$F$4:$F1000,"Atrasado") -> 4 | E20: =COUNTIFS(Gestao!$C$4:$C1000,"Preliminares",Gestao!$F$4:$F1000,"Em andamento") -> 1 | F20: =COUNTIFS(Gestao!$C$4:$C1000,"Preliminares",Gestao!$F$4:$F1000,"A iniciar") -> 0 | H20: Serralheria | I20: =COUNTIF(Detalhamento!$G$9:$G1000,"Serralheria") -> 48 | J20: =COUNTIFS(Detalhamento!$G$9:$G1000,"Serralheria",Detalhamento!$H$9:$H1000,"Concluído") -> 5 | K20: =IFERROR(J20/I20,0) -> 0.10416667 | L20: =IFERROR(REPT("▮",ROUND(K20*12,0)),"") -> ▮
B21: M1 - Novo Arquivo | C21: =COUNTIF(Gestao!$C$4:$C1000,"M1 - Novo Arquivo") -> 12 | D21: =COUNTIFS(Gestao!$C$4:$C1000,"M1 - Novo Arquivo",Gestao!$F$4:$F1000,"Atrasado") -> 0 | E21: =COUNTIFS(Gestao!$C$4:$C1000,"M1 - Novo Arquivo",Gestao!$F$4:$F1000,"Em andamento") -> 0 | F21: =COUNTIFS(Gestao!$C$4:$C1000,"M1 - Novo Arquivo",Gestao!$F$4:$F1000,"A iniciar") -> 12 | H21: Impermeabilizacao | I21: =COUNTIF(Detalhamento!$G$9:$G1000,"Impermeabilizacao") -> 16 | J21: =COUNTIFS(Detalhamento!$G$9:$G1000,"Impermeabilizacao",Detalhamento!$H$9:$H1000,"Concluído") -> 0 | K21: =IFERROR(J21/I21,0) -> 0 | L21: =IFERROR(REPT("▮",ROUND(K21*12,0)),"")
B22: Halls - M1/Terreo/M2 | C22: =COUNTIF(Gestao!$C$4:$C1000,"Halls - M1/Terreo/M2") -> 10 | D22: =COUNTIFS(Gestao!$C$4:$C1000,"Halls - M1/Terreo/M2",Gestao!$F$4:$F1000,"Atrasado") -> 3 | E22: =COUNTIFS(Gestao!$C$4:$C1000,"Halls - M1/Terreo/M2",Gestao!$F$4:$F1000,"Em andamento") -> 1 | F22: =COUNTIFS(Gestao!$C$4:$C1000,"Halls - M1/Terreo/M2",Gestao!$F$4:$F1000,"A iniciar") -> 6 | H22: Elevadores | I22: =COUNTIF(Detalhamento!$G$9:$G1000,"Elevadores") -> 31 | J22: =COUNTIFS(Detalhamento!$G$9:$G1000,"Elevadores",Detalhamento!$H$9:$H1000,"Concluído") -> 0 | K22: =IFERROR(J22/I22,0) -> 0 | L22: =IFERROR(REPT("▮",ROUND(K22*12,0)),"")
B23: Halls - Subsolos | C23: =COUNTIF(Gestao!$C$4:$C1000,"Halls - Subsolos") -> 2 | D23: =COUNTIFS(Gestao!$C$4:$C1000,"Halls - Subsolos",Gestao!$F$4:$F1000,"Atrasado") -> 0 | E23: =COUNTIFS(Gestao!$C$4:$C1000,"Halls - Subsolos",Gestao!$F$4:$F1000,"Em andamento") -> 0 | F23: =COUNTIFS(Gestao!$C$4:$C1000,"Halls - Subsolos",Gestao!$F$4:$F1000,"A iniciar") -> 2 | H23: Preliminares | I23: =COUNTIF(Detalhamento!$G$9:$G1000,"Preliminares") -> 3 | J23: =COUNTIFS(Detalhamento!$G$9:$G1000,"Preliminares",Detalhamento!$H$9:$H1000,"Concluído") -> 1 | K23: =IFERROR(J23/I23,0) -> 0.33333333 | L23: =IFERROR(REPT("▮",ROUND(K23*12,0)),"") -> ▮▮▮▮
H24: Limpeza | I24: =COUNTIF(Detalhamento!$G$9:$G1000,"Limpeza") -> 6 | J24: =COUNTIFS(Detalhamento!$G$9:$G1000,"Limpeza",Detalhamento!$H$9:$H1000,"Concluído") -> 0 | K24: =IFERROR(J24/I24,0) -> 0 | L24: =IFERROR(REPT("▮",ROUND(K24*12,0)),"")
B25: ⚠️ ITENS ATRASADOS (Gestão)
B26: Item | C26: Atividade | D26: Área | E26: Término
B27: =IFERROR(__xludf.DUMMYFUNCTION("IFERROR(QUERY(Gestao!A4:F1000,""select A,B,C,E where F = 'Atrasado' order by E limit 52"",0),""Nenhum atrasado"")"),"1.2") -> 1.2 | C27: =IFERROR(__xludf.DUMMYFUNCTION("""COMPUTED_VALUE"""),"Emissão de ART Obra(Anotação de responsabilidade técnica)") -> Emissão de ART Obra(Anotação de responsabilidade técnica) | D27: =IFERROR(__xludf.DUMMYFUNCTION("""COMPUTED_VALUE"""),"Preliminares") -> Preliminares | E27: =IFERROR(__xludf.DUMMYFUNCTION("""COMPUTED_VALUE"""),46050.0) -> 46050 | H27: FINANCEIRO (consolidado)
B28: =IFERROR(__xludf.DUMMYFUNCTION("""COMPUTED_VALUE"""),"1.3") -> 1.3 | C28: =IFERROR(__xludf.DUMMYFUNCTION("""COMPUTED_VALUE"""),"Mobilização de canteiro e equipes e deslocamento") -> Mobilização de canteiro e equipes e deslocamento | D28: =IFERROR(__xludf.DUMMYFUNCTION("""COMPUTED_VALUE"""),"Preliminares") -> Preliminares | E28: =IFERROR(__xludf.DUMMYFUNCTION("""COMPUTED_VALUE"""),46065.0) -> 46065 | H28: Previsto (R$) | K28: =Orcamentos!$O$6 -> 0
B29: =IFERROR(__xludf.DUMMYFUNCTION("""COMPUTED_VALUE"""),"6.1") -> 6.1 | C29: =IFERROR(__xludf.DUMMYFUNCTION("""COMPUTED_VALUE"""),"Demolicão manual de alvenaria de tijolos furados, contrapiso de 5 cm no deposito 5, inclusive empilhamento dentro do canteiro de servico.") -> Demolicão manual de alvenaria de tijolos furados, contrapiso de 5 cm no deposito 5, inclusive empilhamento dentro do canteiro de servico. | D29: =IFERROR(__xludf.DUMMYFUNCTION("""COMPUTED_VALUE"""),"Andar 9") -> Andar 9 | E29: =IFERROR(__xludf.DUMMYFUNCTION("""COMPUTED_VALUE"""),46072.0) -> 46072 | H29: Real / Devido (R$) | K29: =Orcamentos!$P$6 -> 0
B30: =IFERROR(__xludf.DUMMYFUNCTION("""COMPUTED_VALUE"""),"6.6") -> 6.6 | C30: =IFERROR(__xludf.DUMMYFUNCTION("""COMPUTED_VALUE"""),"Retiro porta existente.") -> Retiro porta existente. | D30: =IFERROR(__xludf.DUMMYFUNCTION("""COMPUTED_VALUE"""),"Andar 9") -> Andar 9 | E30: =IFERROR(__xludf.DUMMYFUNCTION("""COMPUTED_VALUE"""),46072.0) -> 46072 | H30: Pago (R$) | K30: =Orcamentos!$Q$6 -> 0
B31: =IFERROR(__xludf.DUMMYFUNCTION("""COMPUTED_VALUE"""),"1.1") -> 1.1 | C31: =IFERROR(__xludf.DUMMYFUNCTION("""COMPUTED_VALUE"""),"Gerenciamento técnico de obra - 2 Engenheiros (40h/mês) , assistente tecnico (40h/mês) , mestre de obra (160h/mês)") -> Gerenciamento técnico de obra - 2 Engenheiros (40h/mês) , assistente tecnico (40h/mês) , mestre de obra (160h/mês) | D31: =IFERROR(__xludf.DUMMYFUNCTION("""COMPUTED_VALUE"""),"Preliminares") -> Preliminares | E31: =IFERROR(__xludf.DUMMYFUNCTION("""COMPUTED_VALUE"""),46073.0) -> 46073 | H31: Saldo (R$) | K31: =Orcamentos!$R$6 -> 0
B32: =IFERROR(__xludf.DUMMYFUNCTION("""COMPUTED_VALUE"""),"1.4") -> 1.4 | C32: =IFERROR(__xludf.DUMMYFUNCTION("""COMPUTED_VALUE"""),"Tapume de vedacao ou protecao, executado com chapas de compensado, tipo chapa resinada ou similar, com 6mm de espessura, exclusive pintura. Proteção chegada elvadores;.") -> Tapume de vedacao ou protecao, executado com chapas de compensado, tipo chapa resinada ou similar, com 6mm de espessura, exclusive pintura. Proteção chegada elvadores;. | D32: =IFERROR(__xludf.DUMMYFUNCTION("""COMPUTED_VALUE"""),"Preliminares") -> Preliminares | E32: =IFERROR(__xludf.DUMMYFUNCTION("""COMPUTED_VALUE"""),46080.0) -> 46080 | H32: A pagar (R$) | K32: =Pagamentos!$C$2
B33: =IFERROR(__xludf.DUMMYFUNCTION("""COMPUTED_VALUE"""),"5.7") -> 5.7 | C33: =IFERROR(__xludf.DUMMYFUNCTION("""COMPUTED_VALUE"""),"Retiro porta existente.") -> Retiro porta existente. | D33: =IFERROR(__xludf.DUMMYFUNCTION("""COMPUTED_VALUE"""),"Andar 8") -> Andar 8 | E33: =IFERROR(__xludf.DUMMYFUNCTION("""COMPUTED_VALUE"""),46080.0) -> 46080 | H33: Vencendo 7 dias (R$) | K33: =Pagamentos!$G$2
B34: =IFERROR(__xludf.DUMMYFUNCTION("""COMPUTED_VALUE"""),"5.11") -> 5.11 | C34: =IFERROR(__xludf.DUMMYFUNCTION("""COMPUTED_VALUE"""),"Realização da nova janela considerando as aberturas já existentes e os fechamentos com tijolos onde necessarios.") -> Realização da nova janela considerando as aberturas já existentes e os fechamentos com tijolos onde necessarios. | D34: =IFERROR(__xludf.DUMMYFUNCTION("""COMPUTED_VALUE"""),"Andar 8") -> Andar 8 | E34: =IFERROR(__xludf.DUMMYFUNCTION("""COMPUTED_VALUE"""),46086.0) -> 46086 | H34: Pagamentos atrasados (R$) | K34: =Pagamentos!$I$2
B35: =IFERROR(__xludf.DUMMYFUNCTION("""COMPUTED_VALUE"""),"5.1") -> 5.1 | C35: =IFERROR(__xludf.DUMMYFUNCTION("""COMPUTED_VALUE"""),"Demolicão manual de alvenaria de tijolos furados, contrapiso de 5 cm no deposito 5, inclusive empilhamento dentro do canteiro de servico.") -> Demolicão manual de alvenaria de tijolos furados, contrapiso de 5 cm no deposito 5, inclusive empilhamento dentro do canteiro de servico. | D35: =IFERROR(__xludf.DUMMYFUNCTION("""COMPUTED_VALUE"""),"Andar 8") -> Andar 8 | E35: =IFERROR(__xludf.DUMMYFUNCTION("""COMPUTED_VALUE"""),46094.0) -> 46094
B36: =IFERROR(__xludf.DUMMYFUNCTION("""COMPUTED_VALUE"""),"5.9") -> 5.9 | C36: =IFERROR(__xludf.DUMMYFUNCTION("""COMPUTED_VALUE"""),"Demolição do suporte em concreto do velho sistema de ar-condicionado e nivelamento bruto do piso") -> Demolição do suporte em concreto do velho sistema de ar-condicionado e nivelamento bruto do piso | D36: =IFERROR(__xludf.DUMMYFUNCTION("""COMPUTED_VALUE"""),"Andar 8") -> Andar 8 | E36: =IFERROR(__xludf.DUMMYFUNCTION("""COMPUTED_VALUE"""),46094.0) -> 46094
B37: =IFERROR(__xludf.DUMMYFUNCTION("""COMPUTED_VALUE"""),"5.2") -> 5.2 | C37: =IFERROR(__xludf.DUMMYFUNCTION("""COMPUTED_VALUE"""),"Demolição controlada e monitrada para rebaixamento da laje e abertura na laje e paredes em concreto armado") -> Demolição controlada e monitrada para rebaixamento da laje e abertura na laje e paredes em concreto armado | D37: =IFERROR(__xludf.DUMMYFUNCTION("""COMPUTED_VALUE"""),"Andar 8") -> Andar 8 | E37: =IFERROR(__xludf.DUMMYFUNCTION("""COMPUTED_VALUE"""),46103.0) -> 46103
B38: =IFERROR(__xludf.DUMMYFUNCTION("""COMPUTED_VALUE"""),"5.8") -> 5.8 | C38: =IFERROR(__xludf.DUMMYFUNCTION("""COMPUTED_VALUE"""),"Demolição controlada e monitorada do cocreto para abertura das novas portas") -> Demolição controlada e monitorada do cocreto para abertura das novas portas | D38: =IFERROR(__xludf.DUMMYFUNCTION("""COMPUTED_VALUE"""),"Andar 8") -> Andar 8 | E38: =IFERROR(__xludf.DUMMYFUNCTION("""COMPUTED_VALUE"""),46122.0) -> 46122
B39: =IFERROR(__xludf.DUMMYFUNCTION("""COMPUTED_VALUE"""),"6.2") -> 6.2 | C39: =IFERROR(__xludf.DUMMYFUNCTION("""COMPUTED_VALUE"""),"Demolição controlada e monitrada para rebaixamento da laje e abertura na laje e paredes em concreto armado") -> Demolição controlada e monitrada para rebaixamento da laje e abertura na laje e paredes em concreto armado | D39: =IFERROR(__xludf.DUMMYFUNCTION("""COMPUTED_VALUE"""),"Andar 9") -> Andar 9 | E39: =IFERROR(__xludf.DUMMYFUNCTION("""COMPUTED_VALUE"""),46135.0) -> 46135
B40: =IFERROR(__xludf.DUMMYFUNCTION("""COMPUTED_VALUE"""),"5.13") -> 5.13 | C40: =IFERROR(__xludf.DUMMYFUNCTION("""COMPUTED_VALUE"""),"Construção da separação das duas novas portas e da parede de separação do novo corredor verso externo.") -> Construção da separação das duas novas portas e da parede de separação do novo corredor verso externo. | D40: =IFERROR(__xludf.DUMMYFUNCTION("""COMPUTED_VALUE"""),"Andar 8") -> Andar 8 | E40: =IFERROR(__xludf.DUMMYFUNCTION("""COMPUTED_VALUE"""),46136.0) -> 46136
B41: =IFERROR(__xludf.DUMMYFUNCTION("""COMPUTED_VALUE"""),"5.15") -> 5.15 | C41: =IFERROR(__xludf.DUMMYFUNCTION("""COMPUTED_VALUE"""),"Fornecimento e execução de parede em alvenaria com bloco cimentício, considerando chapisco e reboco (desonerado)") -> Fornecimento e execução de parede em alvenaria com bloco cimentício, considerando chapisco e reboco (desonerado) | D41: =IFERROR(__xludf.DUMMYFUNCTION("""COMPUTED_VALUE"""),"Andar 8") -> Andar 8 | E41: =IFERROR(__xludf.DUMMYFUNCTION("""COMPUTED_VALUE"""),46136.0) -> 46136
B42: =IFERROR(__xludf.DUMMYFUNCTION("""COMPUTED_VALUE"""),"5.32") -> 5.32 | C42: =IFERROR(__xludf.DUMMYFUNCTION("""COMPUTED_VALUE"""),"Fornecimento e instalação de QUADRO DE DITRIBUÇÃO completo, embutido ou sobreposto, em caixa metálica ou termoplástica, com porta, pintura eletrostática e grau de proteção mínimo IP40. Equipado com disjuntores termomagnéticos monopolares, bipolares ou tri"&"polares conforme projeto, barramentos de fase, neutro e terra, trilho DIN, identificação dos circuitos e acessórios. Inclusos todos os materiais, componentes, mão de obra para montagem, fixação, aterramento, testes e conformidade com as normas técnicas vi"&"gentes (NBR 5410 e NR-10).") -> Fornecimento e instalação de QUADRO DE DITRIBUÇÃO completo, embutido ou sobreposto, em caixa metálica ou termoplástica, com porta, pintura eletrostática e grau de proteção mínimo IP40. Equipado com disjuntores termomagnéticos monopolares, bipolares ou tripolares conforme projeto, barramentos de fase, neutro e terra, trilho DIN, identificação dos circuitos e acessórios. Inclusos todos os materiais, componentes, mão de obra para montagem, fixação, aterramento, testes e conformidade com as normas técnicas vigentes (NBR 5410 e NR-10). | D42: =IFERROR(__xludf.DUMMYFUNCTION("""COMPUTED_VALUE"""),"Andar 8") -> Andar 8 | E42: =IFERROR(__xludf.DUMMYFUNCTION("""COMPUTED_VALUE"""),46142.0) -> 46142
B43: =IFERROR(__xludf.DUMMYFUNCTION("""COMPUTED_VALUE"""),"5.33") -> 5.33 | C43: =IFERROR(__xludf.DUMMYFUNCTION("""COMPUTED_VALUE"""),"Execução de ponto elétrico completo embutido, composto por 1 tomada 2P+T 20A, 220V e 1 ponto de luz (sem luminária), com fornecimento e instalação de eletrodutos rígidos PVC, caixas de embutir, cabos de cobre ( 25 tomadas + 25 ponto de luz) antichama (fas"&"e, neutro e terra), conectores, suporte e espelho. Inclui instalação da infraestrutura embutida em alvenaria, passagem dos condutores, fixação dos mecanismos, identificação dos circuitos e testes de funcionamento, conforme NBR 5410 e NR-10.") -> Execução de ponto elétrico completo embutido, composto por 1 tomada 2P+T 20A, 220V e 1 ponto de luz (sem luminária), com fornecimento e instalação de eletrodutos rígidos PVC, caixas de embutir, cabos de cobre ( 25 tomadas + 25 ponto de luz) antichama (fase, neutro e terra), conectores, suporte e espelho. Inclui instalação da infraestrutura embutida em alvenaria, passagem dos condutores, fixação dos mecanismos, identificação dos circuitos e testes de funcionamento, conforme NBR 5410 e NR-10. | D43: =IFERROR(__xludf.DUMMYFUNCTION("""COMPUTED_VALUE"""),"Andar 8") -> Andar 8 | E43: =IFERROR(__xludf.DUMMYFUNCTION("""COMPUTED_VALUE"""),46142.0) -> 46142
...

Sheet Gestao
A1: NICE ENGENHARIA | D1: Plano de Obra - Consulado Geral da Itália
D2: GESTÃO - visão geral por item. Inclui rotina de aditivos.
A4: Total de itens | D4: Atrasados | J4: A iniciar | M4: Finalizados | N4: Avanco da obra
A5: =COUNTA(A8:A201) -> 164 | D5: =COUNTIF(F8:F201,"Atrasado") -> 57 | J5: =COUNTIF(F8:F201,"A iniciar") -> 74 | M5: =COUNTIF($G$8:$G$500,"Finalizado") -> 0 | N5: =IFERROR(SUM(H8:H201)/COUNTA(A8:A201),0) -> 0
A7: Item | B7: Atividade | C7: Andar / Área | D7: Início | E7: Término | F7: Situação | G7: Andamento | H7: % Avanco | I7: Pessoas (status) | J7: Docs (status) | K7: Materiais (status) | L7: Ferramentas (status) | M7: Equipamentos (status) | N7: Observações | O7: Tipo
A8: 1.1 | B8: Gerenciamento técnico de obra - 2 Engenheiros (40h/mês) , assistente tecnico (40h/mês) , mestre de obra (160h/mês) | C8: Preliminares | D8: 46047 | E8: 46073 | F8: =IF(OR($D8="",$E8=""),"Sem data",IF($E8<TODAY(),"Atrasado",IF($D8>TODAY(),"A iniciar","Em andamento"))) -> Atrasado | I8: =IF(COUNTIF(Detalhamento!A9:A329,A8)=0,"-",IF(COUNTIFS(Detalhamento!A9:A329,A8,Detalhamento!J9:J329,"Pendente")>0,"Pendente",IF(COUNTIFS(Detalhamento!A9:A329,A8,Detalhamento!J9:J329,"OK")>0,"OK","-"))) -> - | J8: =IF(COUNTIF(Detalhamento!A9:A329,A8)=0,"-",IF(COUNTIFS(Detalhamento!A9:A329,A8,Detalhamento!K9:K329,"Pendente")>0,"Pendente",IF(COUNTIFS(Detalhamento!A9:A329,A8,Detalhamento!K9:K329,"OK")>0,"OK","-"))) -> - | K8: =IF(COUNTIF(Detalhamento!A9:A329,A8)=0,"-",IF(COUNTIFS(Detalhamento!A9:A329,A8,Detalhamento!L9:L329,"Pendente")>0,"Pendente",IF(COUNTIFS(Detalhamento!A9:A329,A8,Detalhamento!L9:L329,"OK")>0,"OK","-"))) -> - | L8: =IF(COUNTIF(Detalhamento!A9:A329,A8)=0,"-",IF(COUNTIFS(Detalhamento!A9:A329,A8,Detalhamento!M9:M329,"Pendente")>0,"Pendente",IF(COUNTIFS(Detalhamento!A9:A329,A8,Detalhamento!M9:M329,"OK")>0,"OK","-"))) -> - | M8: =IF(COUNTIF(Detalhamento!A9:A329,A8)=0,"-",IF(COUNTIFS(Detalhamento!A9:A329,A8,Detalhamento!N9:N329,"Pendente")>0,"Pendente",IF(COUNTIFS(Detalhamento!A9:A329,A8,Detalhamento!N9:N329,"OK")>0,"OK","-"))) -> - | O8: Original | P8: =IF(A8="",0,COUNTIF(Detalhamento!A9:A329,A8)) -> 0 | Q8: =IF(A8="",0,COUNTIFS(Detalhamento!A9:A329,A8,Detalhamento!H9:H329,"Concluído")) -> 0 | R8: =IFERROR(IF(P8=0,"",Q8/P8),"")
A9: 1.2 | B9: Emissão de ART Obra(Anotação de responsabilidade técnica) | C9: Preliminares | D9: 46050 | E9: 46050 | F9: =IF(OR($D9="",$E9=""),"Sem data",IF($E9<TODAY(),"Atrasado",IF($D9>TODAY(),"A iniciar","Em andamento"))) -> Atrasado | I9: =IF(COUNTIF(Detalhamento!A9:A329,A9)=0,"-",IF(COUNTIFS(Detalhamento!A9:A329,A9,Detalhamento!J9:J329,"Pendente")>0,"Pendente",IF(COUNTIFS(Detalhamento!A9:A329,A9,Detalhamento!J9:J329,"OK")>0,"OK","-"))) -> - | J9: =IF(COUNTIF(Detalhamento!A9:A329,A9)=0,"-",IF(COUNTIFS(Detalhamento!A9:A329,A9,Detalhamento!K9:K329,"Pendente")>0,"Pendente",IF(COUNTIFS(Detalhamento!A9:A329,A9,Detalhamento!K9:K329,"OK")>0,"OK","-"))) -> - | K9: =IF(COUNTIF(Detalhamento!A9:A329,A9)=0,"-",IF(COUNTIFS(Detalhamento!A9:A329,A9,Detalhamento!L9:L329,"Pendente")>0,"Pendente",IF(COUNTIFS(Detalhamento!A9:A329,A9,Detalhamento!L9:L329,"OK")>0,"OK","-"))) -> - | L9: =IF(COUNTIF(Detalhamento!A9:A329,A9)=0,"-",IF(COUNTIFS(Detalhamento!A9:A329,A9,Detalhamento!M9:M329,"Pendente")>0,"Pendente",IF(COUNTIFS(Detalhamento!A9:A329,A9,Detalhamento!M9:M329,"OK")>0,"OK","-"))) -> - | M9: =IF(COUNTIF(Detalhamento!A9:A329,A9)=0,"-",IF(COUNTIFS(Detalhamento!A9:A329,A9,Detalhamento!N9:N329,"Pendente")>0,"Pendente",IF(COUNTIFS(Detalhamento!A9:A329,A9,Detalhamento!N9:N329,"OK")>0,"OK","-"))) -> - | O9: Original | P9: =IF(A9="",0,COUNTIF(Detalhamento!A9:A329,A9)) -> 1 | Q9: =IF(A9="",0,COUNTIFS(Detalhamento!A9:A329,A9,Detalhamento!H9:H329,"Concluído")) -> 1 | R9: =IFERROR(IF(P9=0,"",Q9/P9),"") -> 1
A10: 1.3 | B10: Mobilização de canteiro e equipes e deslocamento | C10: Preliminares | D10: 46050 | E10: 46065 | F10: =IF(OR($D10="",$E10=""),"Sem data",IF($E10<TODAY(),"Atrasado",IF($D10>TODAY(),"A iniciar","Em andamento"))) -> Atrasado | I10: =IF(COUNTIF(Detalhamento!A9:A329,A10)=0,"-",IF(COUNTIFS(Detalhamento!A9:A329,A10,Detalhamento!J9:J329,"Pendente")>0,"Pendente",IF(COUNTIFS(Detalhamento!A9:A329,A10,Detalhamento!J9:J329,"OK")>0,"OK","-"))) -> - | J10: =IF(COUNTIF(Detalhamento!A9:A329,A10)=0,"-",IF(COUNTIFS(Detalhamento!A9:A329,A10,Detalhamento!K9:K329,"Pendente")>0,"Pendente",IF(COUNTIFS(Detalhamento!A9:A329,A10,Detalhamento!K9:K329,"OK")>0,"OK","-"))) -> - | K10: =IF(COUNTIF(Detalhamento!A9:A329,A10)=0,"-",IF(COUNTIFS(Detalhamento!A9:A329,A10,Detalhamento!L9:L329,"Pendente")>0,"Pendente",IF(COUNTIFS(Detalhamento!A9:A329,A10,Detalhamento!L9:L329,"OK")>0,"OK","-"))) -> - | L10: =IF(COUNTIF(Detalhamento!A9:A329,A10)=0,"-",IF(COUNTIFS(Detalhamento!A9:A329,A10,Detalhamento!M9:M329,"Pendente")>0,"Pendente",IF(COUNTIFS(Detalhamento!A9:A329,A10,Detalhamento!M9:M329,"OK")>0,"OK","-"))) -> - | M10: =IF(COUNTIF(Detalhamento!A9:A329,A10)=0,"-",IF(COUNTIFS(Detalhamento!A9:A329,A10,Detalhamento!N9:N329,"Pendente")>0,"Pendente",IF(COUNTIFS(Detalhamento!A9:A329,A10,Detalhamento!N9:N329,"OK")>0,"OK","-"))) -> - | O10: Original | P10: =IF(A10="",0,COUNTIF(Detalhamento!A9:A329,A10)) -> 1 | Q10: =IF(A10="",0,COUNTIFS(Detalhamento!A9:A329,A10,Detalhamento!H9:H329,"Concluído")) -> 0 | R10: =IFERROR(IF(P10=0,"",Q10/P10),"") -> 0
A11: 1.4 | B11: Tapume de vedacao ou protecao, executado com chapas de compensado, tipo chapa resinada ou similar, com 6mm de espessura, exclusive pintura. Proteção chegada elvadores;. | C11: Preliminares | D11: 46050 | E11: 46080 | F11: =IF(OR($D11="",$E11=""),"Sem data",IF($E11<TODAY(),"Atrasado",IF($D11>TODAY(),"A iniciar","Em andamento"))) -> Atrasado | I11: =IF(COUNTIF(Detalhamento!A9:A329,A11)=0,"-",IF(COUNTIFS(Detalhamento!A9:A329,A11,Detalhamento!J9:J329,"Pendente")>0,"Pendente",IF(COUNTIFS(Detalhamento!A9:A329,A11,Detalhamento!J9:J329,"OK")>0,"OK","-"))) -> - | J11: =IF(COUNTIF(Detalhamento!A9:A329,A11)=0,"-",IF(COUNTIFS(Detalhamento!A9:A329,A11,Detalhamento!K9:K329,"Pendente")>0,"Pendente",IF(COUNTIFS(Detalhamento!A9:A329,A11,Detalhamento!K9:K329,"OK")>0,"OK","-"))) -> - | K11: =IF(COUNTIF(Detalhamento!A9:A329,A11)=0,"-",IF(COUNTIFS(Detalhamento!A9:A329,A11,Detalhamento!L9:L329,"Pendente")>0,"Pendente",IF(COUNTIFS(Detalhamento!A9:A329,A11,Detalhamento!L9:L329,"OK")>0,"OK","-"))) -> - | L11: =IF(COUNTIF(Detalhamento!A9:A329,A11)=0,"-",IF(COUNTIFS(Detalhamento!A9:A329,A11,Detalhamento!M9:M329,"Pendente")>0,"Pendente",IF(COUNTIFS(Detalhamento!A9:A329,A11,Detalhamento!M9:M329,"OK")>0,"OK","-"))) -> - | M11: =IF(COUNTIF(Detalhamento!A9:A329,A11)=0,"-",IF(COUNTIFS(Detalhamento!A9:A329,A11,Detalhamento!N9:N329,"Pendente")>0,"Pendente",IF(COUNTIFS(Detalhamento!A9:A329,A11,Detalhamento!N9:N329,"OK")>0,"OK","-"))) -> - | O11: Original | P11: =IF(A11="",0,COUNTIF(Detalhamento!A9:A329,A11)) -> 1 | Q11: =IF(A11="",0,COUNTIFS(Detalhamento!A9:A329,A11,Detalhamento!H9:H329,"Concluído")) -> 0 | R11: =IFERROR(IF(P11=0,"",Q11/P11),"") -> 0
A12: 1.5 | B12: Limpeza permanente de obra | C12: Preliminares | D12: 46047 | E12: 46408 | F12: =IF(OR($D12="",$E12=""),"Sem data",IF($E12<TODAY(),"Atrasado",IF($D12>TODAY(),"A iniciar","Em andamento"))) -> Em andamento | I12: =IF(COUNTIF(Detalhamento!A9:A329,A12)=0,"-",IF(COUNTIFS(Detalhamento!A9:A329,A12,Detalhamento!J9:J329,"Pendente")>0,"Pendente",IF(COUNTIFS(Detalhamento!A9:A329,A12,Detalhamento!J9:J329,"OK")>0,"OK","-"))) -> - | J12: =IF(COUNTIF(Detalhamento!A9:A329,A12)=0,"-",IF(COUNTIFS(Detalhamento!A9:A329,A12,Detalhamento!K9:K329,"Pendente")>0,"Pendente",IF(COUNTIFS(Detalhamento!A9:A329,A12,Detalhamento!K9:K329,"OK")>0,"OK","-"))) -> - | K12: =IF(COUNTIF(Detalhamento!A9:A329,A12)=0,"-",IF(COUNTIFS(Detalhamento!A9:A329,A12,Detalhamento!L9:L329,"Pendente")>0,"Pendente",IF(COUNTIFS(Detalhamento!A9:A329,A12,Detalhamento!L9:L329,"OK")>0,"OK","-"))) -> - | L12: =IF(COUNTIF(Detalhamento!A9:A329,A12)=0,"-",IF(COUNTIFS(Detalhamento!A9:A329,A12,Detalhamento!M9:M329,"Pendente")>0,"Pendente",IF(COUNTIFS(Detalhamento!A9:A329,A12,Detalhamento!M9:M329,"OK")>0,"OK","-"))) -> - | M12: =IF(COUNTIF(Detalhamento!A9:A329,A12)=0,"-",IF(COUNTIFS(Detalhamento!A9:A329,A12,Detalhamento!N9:N329,"Pendente")>0,"Pendente",IF(COUNTIFS(Detalhamento!A9:A329,A12,Detalhamento!N9:N329,"OK")>0,"OK","-"))) -> - | O12: Original | P12: =IF(A12="",0,COUNTIF(Detalhamento!A9:A329,A12)) -> 1 | Q12: =IF(A12="",0,COUNTIFS(Detalhamento!A9:A329,A12,Detalhamento!H9:H329,"Concluído")) -> 0 | R12: =IFERROR(IF(P12=0,"",Q12/P12),"") -> 0
A13: 2.1 | B13: Demolicão manual de alvenaria de tijolos furados, contrapiso de 5 cm no deposito 5, inclusive empilhamento dentro do canteiro de servico. | C13: Elevadores | D13: 46117 | E13: 46166 | F13: =IF(OR($D13="",$E13=""),"Sem data",IF($E13<TODAY(),"Atrasado",IF($D13>TODAY(),"A iniciar","Em andamento"))) -> Atrasado | I13: =IF(COUNTIF(Detalhamento!A9:A329,A13)=0,"-",IF(COUNTIFS(Detalhamento!A9:A329,A13,Detalhamento!J9:J329,"Pendente")>0,"Pendente",IF(COUNTIFS(Detalhamento!A9:A329,A13,Detalhamento!J9:J329,"OK")>0,"OK","-"))) -> - | J13: =IF(COUNTIF(Detalhamento!A9:A329,A13)=0,"-",IF(COUNTIFS(Detalhamento!A9:A329,A13,Detalhamento!K9:K329,"Pendente")>0,"Pendente",IF(COUNTIFS(Detalhamento!A9:A329,A13,Detalhamento!K9:K329,"OK")>0,"OK","-"))) -> - | K13: =IF(COUNTIF(Detalhamento!A9:A329,A13)=0,"-",IF(COUNTIFS(Detalhamento!A9:A329,A13,Detalhamento!L9:L329,"Pendente")>0,"Pendente",IF(COUNTIFS(Detalhamento!A9:A329,A13,Detalhamento!L9:L329,"OK")>0,"OK","-"))) -> - | L13: =IF(COUNTIF(Detalhamento!A9:A329,A13)=0,"-",IF(COUNTIFS(Detalhamento!A9:A329,A13,Detalhamento!M9:M329,"Pendente")>0,"Pendente",IF(COUNTIFS(Detalhamento!A9:A329,A13,Detalhamento!M9:M329,"OK")>0,"OK","-"))) -> - | M13: =IF(COUNTIF(Detalhamento!A9:A329,A13)=0,"-",IF(COUNTIFS(Detalhamento!A9:A329,A13,Detalhamento!N9:N329,"Pendente")>0,"Pendente",IF(COUNTIFS(Detalhamento!A9:A329,A13,Detalhamento!N9:N329,"OK")>0,"OK","-"))) -> - | O13: Original | P13: =IF(A13="",0,COUNTIF(Detalhamento!A9:A329,A13)) -> 7 | Q13: =IF(A13="",0,COUNTIFS(Detalhamento!A9:A329,A13,Detalhamento!H9:H329,"Concluído")) -> 0 | R13: =IFERROR(IF(P13=0,"",Q13/P13),"") -> 0
A14: 2.2 | B14: Demolição controlada e monitrada para rebaixamento da laje e abertura na laje superior e dos vãos de portas nos andares | C14: Elevadores | D14: 46117 | E14: 46240 | F14: =IF(OR($D14="",$E14=""),"Sem data",IF($E14<TODAY(),"Atrasado",IF($D14>TODAY(),"A iniciar","Em andamento"))) -> Em andamento | I14: =IF(COUNTIF(Detalhamento!A9:A329,A14)=0,"-",IF(COUNTIFS(Detalhamento!A9:A329,A14,Detalhamento!J9:J329,"Pendente")>0,"Pendente",IF(COUNTIFS(Detalhamento!A9:A329,A14,Detalhamento!J9:J329,"OK")>0,"OK","-"))) -> - | J14: =IF(COUNTIF(Detalhamento!A9:A329,A14)=0,"-",IF(COUNTIFS(Detalhamento!A9:A329,A14,Detalhamento!K9:K329,"Pendente")>0,"Pendente",IF(COUNTIFS(Detalhamento!A9:A329,A14,Detalhamento!K9:K329,"OK")>0,"OK","-"))) -> - | K14: =IF(COUNTIF(Detalhamento!A9:A329,A14)=0,"-",IF(COUNTIFS(Detalhamento!A9:A329,A14,Detalhamento!L9:L329,"Pendente")>0,"Pendente",IF(COUNTIFS(Detalhamento!A9:A329,A14,Detalhamento!L9:L329,"OK")>0,"OK","-"))) -> - | L14: =IF(COUNTIF(Detalhamento!A9:A329,A14)=0,"-",IF(COUNTIFS(Detalhamento!A9:A329,A14,Detalhamento!M9:M329,"Pendente")>0,"Pendente",IF(COUNTIFS(Detalhamento!A9:A329,A14,Detalhamento!M9:M329,"OK")>0,"OK","-"))) -> - | M14: =IF(COUNTIF(Detalhamento!A9:A329,A14)=0,"-",IF(COUNTIFS(Detalhamento!A9:A329,A14,Detalhamento!N9:N329,"Pendente")>0,"Pendente",IF(COUNTIFS(Detalhamento!A9:A329,A14,Detalhamento!N9:N329,"OK")>0,"OK","-"))) -> - | O14: Original | P14: =IF(A14="",0,COUNTIF(Detalhamento!A9:A329,A14)) -> 8 | Q14: =IF(A14="",0,COUNTIFS(Detalhamento!A9:A329,A14,Detalhamento!H9:H329,"Concluído")) -> 0 | R14: =IFERROR(IF(P14=0,"",Q14/P14),"") -> 0
A15: 2.3 | B15: Caçamba para entulho 4m³ | C15: Elevadores | D15: 46117 | E15: 46166 | F15: =IF(OR($D15="",$E15=""),"Sem data",IF($E15<TODAY(),"Atrasado",IF($D15>TODAY(),"A iniciar","Em andamento"))) -> Atrasado | I15: =IF(COUNTIF(Detalhamento!A9:A329,A15)=0,"-",IF(COUNTIFS(Detalhamento!A9:A329,A15,Detalhamento!J9:J329,"Pendente")>0,"Pendente",IF(COUNTIFS(Detalhamento!A9:A329,A15,Detalhamento!J9:J329,"OK")>0,"OK","-"))) -> - | J15: =IF(COUNTIF(Detalhamento!A9:A329,A15)=0,"-",IF(COUNTIFS(Detalhamento!A9:A329,A15,Detalhamento!K9:K329,"Pendente")>0,"Pendente",IF(COUNTIFS(Detalhamento!A9:A329,A15,Detalhamento!K9:K329,"OK")>0,"OK","-"))) -> - | K15: =IF(COUNTIF(Detalhamento!A9:A329,A15)=0,"-",IF(COUNTIFS(Detalhamento!A9:A329,A15,Detalhamento!L9:L329,"Pendente")>0,"Pendente",IF(COUNTIFS(Detalhamento!A9:A329,A15,Detalhamento!L9:L329,"OK")>0,"OK","-"))) -> - | L15: =IF(COUNTIF(Detalhamento!A9:A329,A15)=0,"-",IF(COUNTIFS(Detalhamento!A9:A329,A15,Detalhamento!M9:M329,"Pendente")>0,"Pendente",IF(COUNTIFS(Detalhamento!A9:A329,A15,Detalhamento!M9:M329,"OK")>0,"OK","-"))) -> - | M15: =IF(COUNTIF(Detalhamento!A9:A329,A15)=0,"-",IF(COUNTIFS(Detalhamento!A9:A329,A15,Detalhamento!N9:N329,"Pendente")>0,"Pendente",IF(COUNTIFS(Detalhamento!A9:A329,A15,Detalhamento!N9:N329,"OK")>0,"OK","-"))) -> - | O15: Original | P15: =IF(A15="",0,COUNTIF(Detalhamento!A9:A329,A15)) -> 5 | Q15: =IF(A15="",0,COUNTIFS(Detalhamento!A9:A329,A15,Detalhamento!H9:H329,"Concluído")) -> 0 | R15: =IFERROR(IF(P15=0,"",Q15/P15),"") -> 0
A16: 2.4 | B16: Transporte de entulho e grades | C16: Elevadores | D16: 46117 | E16: 46166 | F16: =IF(OR($D16="",$E16=""),"Sem data",IF($E16<TODAY(),"Atrasado",IF($D16>TODAY(),"A iniciar","Em andamento"))) -> Atrasado | I16: =IF(COUNTIF(Detalhamento!A9:A329,A16)=0,"-",IF(COUNTIFS(Detalhamento!A9:A329,A16,Detalhamento!J9:J329,"Pendente")>0,"Pendente",IF(COUNTIFS(Detalhamento!A9:A329,A16,Detalhamento!J9:J329,"OK")>0,"OK","-"))) -> - | J16: =IF(COUNTIF(Detalhamento!A9:A329,A16)=0,"-",IF(COUNTIFS(Detalhamento!A9:A329,A16,Detalhamento!K9:K329,"Pendente")>0,"Pendente",IF(COUNTIFS(Detalhamento!A9:A329,A16,Detalhamento!K9:K329,"OK")>0,"OK","-"))) -> - | K16: =IF(COUNTIF(Detalhamento!A9:A329,A16)=0,"-",IF(COUNTIFS(Detalhamento!A9:A329,A16,Detalhamento!L9:L329,"Pendente")>0,"Pendente",IF(COUNTIFS(Detalhamento!A9:A329,A16,Detalhamento!L9:L329,"OK")>0,"OK","-"))) -> - | L16: =IF(COUNTIF(Detalhamento!A9:A329,A16)=0,"-",IF(COUNTIFS(Detalhamento!A9:A329,A16,Detalhamento!M9:M329,"Pendente")>0,"Pendente",IF(COUNTIFS(Detalhamento!A9:A329,A16,Detalhamento!M9:M329,"OK")>0,"OK","-"))) -> - | M16: =IF(COUNTIF(Detalhamento!A9:A329,A16)=0,"-",IF(COUNTIFS(Detalhamento!A9:A329,A16,Detalhamento!N9:N329,"Pendente")>0,"Pendente",IF(COUNTIFS(Detalhamento!A9:A329,A16,Detalhamento!N9:N329,"OK")>0,"OK","-"))) -> - | O16: Original | P16: =IF(A16="",0,COUNTIF(Detalhamento!A9:A329,A16)) -> 5 | Q16: =IF(A16="",0,COUNTIFS(Detalhamento!A9:A329,A16,Detalhamento!H9:H329,"Concluído")) -> 0 | R16: =IFERROR(IF(P16=0,"",Q16/P16),"") -> 0
A17: 2.5 | B17: Caçamba para entulho 4m³ | C17: Elevadores | D17: 46169 | E17: 46243 | F17: =IF(OR($D17="",$E17=""),"Sem data",IF($E17<TODAY(),"Atrasado",IF($D17>TODAY(),"A iniciar","Em andamento"))) -> Em andamento | I17: =IF(COUNTIF(Detalhamento!A9:A329,A17)=0,"-",IF(COUNTIFS(Detalhamento!A9:A329,A17,Detalhamento!J9:J329,"Pendente")>0,"Pendente",IF(COUNTIFS(Detalhamento!A9:A329,A17,Detalhamento!J9:J329,"OK")>0,"OK","-"))) -> - | J17: =IF(COUNTIF(Detalhamento!A9:A329,A17)=0,"-",IF(COUNTIFS(Detalhamento!A9:A329,A17,Detalhamento!K9:K329,"Pendente")>0,"Pendente",IF(COUNTIFS(Detalhamento!A9:A329,A17,Detalhamento!K9:K329,"OK")>0,"OK","-"))) -> - | K17: =IF(COUNTIF(Detalhamento!A9:A329,A17)=0,"-",IF(COUNTIFS(Detalhamento!A9:A329,A17,Detalhamento!L9:L329,"Pendente")>0,"Pendente",IF(COUNTIFS(Detalhamento!A9:A329,A17,Detalhamento!L9:L329,"OK")>0,"OK","-"))) -> - | L17: =IF(COUNTIF(Detalhamento!A9:A329,A17)=0,"-",IF(COUNTIFS(Detalhamento!A9:A329,A17,Detalhamento!M9:M329,"Pendente")>0,"Pendente",IF(COUNTIFS(Detalhamento!A9:A329,A17,Detalhamento!M9:M329,"OK")>0,"OK","-"))) -> - | M17: =IF(COUNTIF(Detalhamento!A9:A329,A17)=0,"-",IF(COUNTIFS(Detalhamento!A9:A329,A17,Detalhamento!N9:N329,"Pendente")>0,"Pendente",IF(COUNTIFS(Detalhamento!A9:A329,A17,Detalhamento!N9:N329,"OK")>0,"OK","-"))) -> - | O17: Original | P17: =IF(A17="",0,COUNTIF(Detalhamento!A9:A329,A17)) -> 5 | Q17: =IF(A17="",0,COUNTIFS(Detalhamento!A9:A329,A17,Detalhamento!H9:H329,"Concluído")) -> 0 | R17: =IFERROR(IF(P17=0,"",Q17/P17),"") -> 0
A18: 2.6 | B18: Transporte de entulho | C18: Elevadores | D18: 46169 | E18: 46243 | F18: =IF(OR($D18="",$E18=""),"Sem data",IF($E18<TODAY(),"Atrasado",IF($D18>TODAY(),"A iniciar","Em andamento"))) -> Em andamento | I18: =IF(COUNTIF(Detalhamento!A9:A329,A18)=0,"-",IF(COUNTIFS(Detalhamento!A9:A329,A18,Detalhamento!J9:J329,"Pendente")>0,"Pendente",IF(COUNTIFS(Detalhamento!A9:A329,A18,Detalhamento!J9:J329,"OK")>0,"OK","-"))) -> - | J18: =IF(COUNTIF(Detalhamento!A9:A329,A18)=0,"-",IF(COUNTIFS(Detalhamento!A9:A329,A18,Detalhamento!K9:K329,"Pendente")>0,"Pendente",IF(COUNTIFS(Detalhamento!A9:A329,A18,Detalhamento!K9:K329,"OK")>0,"OK","-"))) -> - | K18: =IF(COUNTIF(Detalhamento!A9:A329,A18)=0,"-",IF(COUNTIFS(Detalhamento!A9:A329,A18,Detalhamento!L9:L329,"Pendente")>0,"Pendente",IF(COUNTIFS(Detalhamento!A9:A329,A18,Detalhamento!L9:L329,"OK")>0,"OK","-"))) -> - | L18: =IF(COUNTIF(Detalhamento!A9:A329,A18)=0,"-",IF(COUNTIFS(Detalhamento!A9:A329,A18,Detalhamento!M9:M329,"Pendente")>0,"Pendente",IF(COUNTIFS(Detalhamento!A9:A329,A18,Detalhamento!M9:M329,"OK")>0,"OK","-"))) -> - | M18: =IF(COUNTIF(Detalhamento!A9:A329,A18)=0,"-",IF(COUNTIFS(Detalhamento!A9:A329,A18,Detalhamento!N9:N329,"Pendente")>0,"Pendente",IF(COUNTIFS(Detalhamento!A9:A329,A18,Detalhamento!N9:N329,"OK")>0,"OK","-"))) -> - | O18: Original | P18: =IF(A18="",0,COUNTIF(Detalhamento!A9:A329,A18)) -> 3 | Q18: =IF(A18="",0,COUNTIFS(Detalhamento!A9:A329,A18,Detalhamento!H9:H329,"Concluído")) -> 0 | R18: =IFERROR(IF(P18=0,"",Q18/P18),"") -> 0
A19: 2.7 | B19: Montagem e desmontagem de andaime direcional estrutural com chumbadores e plataforma | C19: Elevadores | D19: 46145 | E19: 46191 | F19: =IF(OR($D19="",$E19=""),"Sem data",IF($E19<TODAY(),"Atrasado",IF($D19>TODAY(),"A iniciar","Em andamento"))) -> Atrasado | I19: =IF(COUNTIF(Detalhamento!A9:A329,A19)=0,"-",IF(COUNTIFS(Detalhamento!A9:A329,A19,Detalhamento!J9:J329,"Pendente")>0,"Pendente",IF(COUNTIFS(Detalhamento!A9:A329,A19,Detalhamento!J9:J329,"OK")>0,"OK","-"))) -> - | J19: =IF(COUNTIF(Detalhamento!A9:A329,A19)=0,"-",IF(COUNTIFS(Detalhamento!A9:A329,A19,Detalhamento!K9:K329,"Pendente")>0,"Pendente",IF(COUNTIFS(Detalhamento!A9:A329,A19,Detalhamento!K9:K329,"OK")>0,"OK","-"))) -> - | K19: =IF(COUNTIF(Detalhamento!A9:A329,A19)=0,"-",IF(COUNTIFS(Detalhamento!A9:A329,A19,Detalhamento!L9:L329,"Pendente")>0,"Pendente",IF(COUNTIFS(Detalhamento!A9:A329,A19,Detalhamento!L9:L329,"OK")>0,"OK","-"))) -> - | L19: =IF(COUNTIF(Detalhamento!A9:A329,A19)=0,"-",IF(COUNTIFS(Detalhamento!A9:A329,A19,Detalhamento!M9:M329,"Pendente")>0,"Pendente",IF(COUNTIFS(Detalhamento!A9:A329,A19,Detalhamento!M9:M329,"OK")>0,"OK","-"))) -> - | M19: =IF(COUNTIF(Detalhamento!A9:A329,A19)=0,"-",IF(COUNTIFS(Detalhamento!A9:A329,A19,Detalhamento!N9:N329,"Pendente")>0,"Pendente",IF(COUNTIFS(Detalhamento!A9:A329,A19,Detalhamento!N9:N329,"OK")>0,"OK","-"))) -> - | O19: Original | P19: =IF(A19="",0,COUNTIF(Detalhamento!A9:A329,A19)) -> 7 | Q19: =IF(A19="",0,COUNTIFS(Detalhamento!A9:A329,A19,Detalhamento!H9:H329,"Concluído")) -> 0 | R19: =IFERROR(IF(P19=0,"",Q19/P19),"") -> 0
A20: 3.1 | B20: Construção do prolongamento da caixa do elevador | C20: Elevadores | D20: 46243 | E20: 46261 | F20: =IF(OR($D20="",$E20=""),"Sem data",IF($E20<TODAY(),"Atrasado",IF($D20>TODAY(),"A iniciar","Em andamento"))) -> A iniciar | I20: =IF(COUNTIF(Detalhamento!A9:A329,A20)=0,"-",IF(COUNTIFS(Detalhamento!A9:A329,A20,Detalhamento!J9:J329,"Pendente")>0,"Pendente",IF(COUNTIFS(Detalhamento!A9:A329,A20,Detalhamento!J9:J329,"OK")>0,"OK","-"))) -> - | J20: =IF(COUNTIF(Detalhamento!A9:A329,A20)=0,"-",IF(COUNTIFS(Detalhamento!A9:A329,A20,Detalhamento!K9:K329,"Pendente")>0,"Pendente",IF(COUNTIFS(Detalhamento!A9:A329,A20,Detalhamento!K9:K329,"OK")>0,"OK","-"))) -> - | K20: =IF(COUNTIF(Detalhamento!A9:A329,A20)=0,"-",IF(COUNTIFS(Detalhamento!A9:A329,A20,Detalhamento!L9:L329,"Pendente")>0,"Pendente",IF(COUNTIFS(Detalhamento!A9:A329,A20,Detalhamento!L9:L329,"OK")>0,"OK","-"))) -> - | L20: =IF(COUNTIF(Detalhamento!A9:A329,A20)=0,"-",IF(COUNTIFS(Detalhamento!A9:A329,A20,Detalhamento!M9:M329,"Pendente")>0,"Pendente",IF(COUNTIFS(Detalhamento!A9:A329,A20,Detalhamento!M9:M329,"OK")>0,"OK","-"))) -> - | M20: =IF(COUNTIF(Detalhamento!A9:A329,A20)=0,"-",IF(COUNTIFS(Detalhamento!A9:A329,A20,Detalhamento!N9:N329,"Pendente")>0,"Pendente",IF(COUNTIFS(Detalhamento!A9:A329,A20,Detalhamento!N9:N329,"OK")>0,"OK","-"))) -> - | O20: Original | P20: =IF(A20="",0,COUNTIF(Detalhamento!A9:A329,A20)) -> 5 | Q20: =IF(A20="",0,COUNTIFS(Detalhamento!A9:A329,A20,Detalhamento!H9:H329,"Concluído")) -> 0 | R20: =IFERROR(IF(P20=0,"",Q20/P20),"") -> 0
A21: 3.2 | B21: Construção da laje de cobertura da torre com Alça para içamento do pistão | C21: Elevadores | D21: 46278 | E21: 46289 | F21: =IF(OR($D21="",$E21=""),"Sem data",IF($E21<TODAY(),"Atrasado",IF($D21>TODAY(),"A iniciar","Em andamento"))) -> A iniciar | I21: =IF(COUNTIF(Detalhamento!A9:A329,A21)=0,"-",IF(COUNTIFS(Detalhamento!A9:A329,A21,Detalhamento!J9:J329,"Pendente")>0,"Pendente",IF(COUNTIFS(Detalhamento!A9:A329,A21,Detalhamento!J9:J329,"OK")>0,"OK","-"))) -> - | J21: =IF(COUNTIF(Detalhamento!A9:A329,A21)=0,"-",IF(COUNTIFS(Detalhamento!A9:A329,A21,Detalhamento!K9:K329,"Pendente")>0,"Pendente",IF(COUNTIFS(Detalhamento!A9:A329,A21,Detalhamento!K9:K329,"OK")>0,"OK","-"))) -> - | K21: =IF(COUNTIF(Detalhamento!A9:A329,A21)=0,"-",IF(COUNTIFS(Detalhamento!A9:A329,A21,Detalhamento!L9:L329,"Pendente")>0,"Pendente",IF(COUNTIFS(Detalhamento!A9:A329,A21,Detalhamento!L9:L329,"OK")>0,"OK","-"))) -> - | L21: =IF(COUNTIF(Detalhamento!A9:A329,A21)=0,"-",IF(COUNTIFS(Detalhamento!A9:A329,A21,Detalhamento!M9:M329,"Pendente")>0,"Pendente",IF(COUNTIFS(Detalhamento!A9:A329,A21,Detalhamento!M9:M329,"OK")>0,"OK","-"))) -> - | M21: =IF(COUNTIF(Detalhamento!A9:A329,A21)=0,"-",IF(COUNTIFS(Detalhamento!A9:A329,A21,Detalhamento!N9:N329,"Pendente")>0,"Pendente",IF(COUNTIFS(Detalhamento!A9:A329,A21,Detalhamento!N9:N329,"OK")>0,"OK","-"))) -> - | O21: Original | P21: =IF(A21="",0,COUNTIF(Detalhamento!A9:A329,A21)) -> 6 | Q21: =IF(A21="",0,COUNTIFS(Detalhamento!A9:A329,A21,Detalhamento!H9:H329,"Concluído")) -> 0 | R21: =IFERROR(IF(P21=0,"",Q21/P21),"") -> 0
A22: 3.3 | B22: Cintas intermediárias em todos os andares | C22: Elevadores | D22: 46145 | E22: 46345 | F22: =IF(OR($D22="",$E22=""),"Sem data",IF($E22<TODAY(),"Atrasado",IF($D22>TODAY(),"A iniciar","Em andamento"))) -> Em andamento | I22: =IF(COUNTIF(Detalhamento!A9:A329,A22)=0,"-",IF(COUNTIFS(Detalhamento!A9:A329,A22,Detalhamento!J9:J329,"Pendente")>0,"Pendente",IF(COUNTIFS(Detalhamento!A9:A329,A22,Detalhamento!J9:J329,"OK")>0,"OK","-"))) -> - | J22: =IF(COUNTIF(Detalhamento!A9:A329,A22)=0,"-",IF(COUNTIFS(Detalhamento!A9:A329,A22,Detalhamento!K9:K329,"Pendente")>0,"Pendente",IF(COUNTIFS(Detalhamento!A9:A329,A22,Detalhamento!K9:K329,"OK")>0,"OK","-"))) -> - | K22: =IF(COUNTIF(Detalhamento!A9:A329,A22)=0,"-",IF(COUNTIFS(Detalhamento!A9:A329,A22,Detalhamento!L9:L329,"Pendente")>0,"Pendente",IF(COUNTIFS(Detalhamento!A9:A329,A22,Detalhamento!L9:L329,"OK")>0,"OK","-"))) -> - | L22: =IF(COUNTIF(Detalhamento!A9:A329,A22)=0,"-",IF(COUNTIFS(Detalhamento!A9:A329,A22,Detalhamento!M9:M329,"Pendente")>0,"Pendente",IF(COUNTIFS(Detalhamento!A9:A329,A22,Detalhamento!M9:M329,"OK")>0,"OK","-"))) -> - | M22: =IF(COUNTIF(Detalhamento!A9:A329,A22)=0,"-",IF(COUNTIFS(Detalhamento!A9:A329,A22,Detalhamento!N9:N329,"Pendente")>0,"Pendente",IF(COUNTIFS(Detalhamento!A9:A329,A22,Detalhamento!N9:N329,"OK")>0,"OK","-"))) -> - | O22: Original | P22: =IF(A22="",0,COUNTIF(Detalhamento!A9:A329,A22)) -> 5 | Q22: =IF(A22="",0,COUNTIFS(Detalhamento!A9:A329,A22,Detalhamento!H9:H329,"Concluído")) -> 0 | R22: =IFERROR(IF(P22=0,"",Q22/P22),"") -> 0
A23: 3.4 | B23: Fechamento das laterais e fundos em alvenaria no prolongamento da torre | C23: Elevadores | D23: 46251 | E23: 46268 | F23: =IF(OR($D23="",$E23=""),"Sem data",IF($E23<TODAY(),"Atrasado",IF($D23>TODAY(),"A iniciar","Em andamento"))) -> A iniciar | I23: =IF(COUNTIF(Detalhamento!A9:A329,A23)=0,"-",IF(COUNTIFS(Detalhamento!A9:A329,A23,Detalhamento!J9:J329,"Pendente")>0,"Pendente",IF(COUNTIFS(Detalhamento!A9:A329,A23,Detalhamento!J9:J329,"OK")>0,"OK","-"))) -> - | J23: =IF(COUNTIF(Detalhamento!A9:A329,A23)=0,"-",IF(COUNTIFS(Detalhamento!A9:A329,A23,Detalhamento!K9:K329,"Pendente")>0,"Pendente",IF(COUNTIFS(Detalhamento!A9:A329,A23,Detalhamento!K9:K329,"OK")>0,"OK","-"))) -> - | K23: =IF(COUNTIF(Detalhamento!A9:A329,A23)=0,"-",IF(COUNTIFS(Detalhamento!A9:A329,A23,Detalhamento!L9:L329,"Pendente")>0,"Pendente",IF(COUNTIFS(Detalhamento!A9:A329,A23,Detalhamento!L9:L329,"OK")>0,"OK","-"))) -> - | L23: =IF(COUNTIF(Detalhamento!A9:A329,A23)=0,"-",IF(COUNTIFS(Detalhamento!A9:A329,A23,Detalhamento!M9:M329,"Pendente")>0,"Pendente",IF(COUNTIFS(Detalhamento!A9:A329,A23,Detalhamento!M9:M329,"OK")>0,"OK","-"))) -> - | M23: =IF(COUNTIF(Detalhamento!A9:A329,A23)=0,"-",IF(COUNTIFS(Detalhamento!A9:A329,A23,Detalhamento!N9:N329,"Pendente")>0,"Pendente",IF(COUNTIFS(Detalhamento!A9:A329,A23,Detalhamento!N9:N329,"OK")>0,"OK","-"))) -> - | O23: Original | P23: =IF(A23="",0,COUNTIF(Detalhamento!A9:A329,A23)) -> 4 | Q23: =IF(A23="",0,COUNTIFS(Detalhamento!A9:A329,A23,Detalhamento!H9:H329,"Concluído")) -> 0 | R23: =IFERROR(IF(P23=0,"",Q23/P23),"") -> 0
A24: 3.5 | B24: Rebocamento no prolongamento da torre | C24: Elevadores | D24: 46254 | E24: 46275 | F24: =IF(OR($D24="",$E24=""),"Sem data",IF($E24<TODAY(),"Atrasado",IF($D24>TODAY(),"A iniciar","Em andamento"))) -> A iniciar | I24: =IF(COUNTIF(Detalhamento!A9:A329,A24)=0,"-",IF(COUNTIFS(Detalhamento!A9:A329,A24,Detalhamento!J9:J329,"Pendente")>0,"Pendente",IF(COUNTIFS(Detalhamento!A9:A329,A24,Detalhamento!J9:J329,"OK")>0,"OK","-"))) -> - | J24: =IF(COUNTIF(Detalhamento!A9:A329,A24)=0,"-",IF(COUNTIFS(Detalhamento!A9:A329,A24,Detalhamento!K9:K329,"Pendente")>0,"Pendente",IF(COUNTIFS(Detalhamento!A9:A329,A24,Detalhamento!K9:K329,"OK")>0,"OK","-"))) -> - | K24: =IF(COUNTIF(Detalhamento!A9:A329,A24)=0,"-",IF(COUNTIFS(Detalhamento!A9:A329,A24,Detalhamento!L9:L329,"Pendente")>0,"Pendente",IF(COUNTIFS(Detalhamento!A9:A329,A24,Detalhamento!L9:L329,"OK")>0,"OK","-"))) -> - | L24: =IF(COUNTIF(Detalhamento!A9:A329,A24)=0,"-",IF(COUNTIFS(Detalhamento!A9:A329,A24,Detalhamento!M9:M329,"Pendente")>0,"Pendente",IF(COUNTIFS(Detalhamento!A9:A329,A24,Detalhamento!M9:M329,"OK")>0,"OK","-"))) -> - | M24: =IF(COUNTIF(Detalhamento!A9:A329,A24)=0,"-",IF(COUNTIFS(Detalhamento!A9:A329,A24,Detalhamento!N9:N329,"Pendente")>0,"Pendente",IF(COUNTIFS(Detalhamento!A9:A329,A24,Detalhamento!N9:N329,"OK")>0,"OK","-"))) -> - | O24: Original | P24: =IF(A24="",0,COUNTIF(Detalhamento!A9:A329,A24)) -> 6 | Q24: =IF(A24="",0,COUNTIFS(Detalhamento!A9:A329,A24,Detalhamento!H9:H329,"Concluído")) -> 0 | R24: =IFERROR(IF(P24=0,"",Q24/P24),"") -> 0
